## 异常

异常：程序在运行过程中可能会发生的错误
抛出（Throw）--> 检测（Try） --> 捕获（Catch）
```cpp
try{
    // 可能抛出异常的语句
}catch(Type1 var1){
    // 处理异常的语句
}catch(const exception &exception){ //可以接收标准异常
    // 处理异常的语句
}catch(...){ //接收任何异常
  ...
}
```
异常可以发生在当前的 try 块中，也可以发生在 try 块所调用的某个函数中，发生异常时会立即终止当前代码，如果当前函数没有catch处理时，异常会抛到上一层函数，直到有catch处理，或最后main()函数抛出异常程序终止
可以有多级catch，用于处理不同的异常返回类型，如果实参和形参的类型不是严格匹配，那么会将实参的类型进行适当的转换，抛出的异常值会赋值给形参

### 异常类
C++本身抛出的异常都是exception的子类，也就是标准异常
![20210319223846](https://i.loli.net/2021/03/19/pURTL5dtn9rZx7K.png)
| 异常                    | 描述                                            |
| ----------------------- | ----------------------------------------------- |
| `std::exception`        | 该异常是所有标准 C++ 异常的父类。               |
| `std::bad_alloc`        | 该异常可以通过 `new` 抛出。                     |
| `std::bad_cast`         | 该异常可以通过 `dynamic_cast` 抛出。            |
| `std::bad_exception`    | 这在处理 C++ 程序中无法预期的异常时非常有用。   |
| `std::bad_typeid`       | 该异常可以通过` typeid` 抛出。                  |
| `std::logic_error`      | 理论上可以通过读取代码来检测到的异常。          |
| `std::domain_error `    | 当使用了一个无效的数学域时，会抛出该异常。      |
| `std::invalid_argument` | 当使用了无效的参数时，会抛出该异常。            |
| `std::length_error`     | 当创建了太长的 `std::string` 时，会抛出该异常。 |
| `std::out_of_range`     | 该异常可以通过方法抛出。                        |
| `std::runtime_error`    | 理论上不可以通过读取代码来检测到的异常。        |
| `std::overflow_error`   | 当发生数学上溢时，会抛出该异常。                |
| `std::range_error`      | 当尝试存储超出范围的值时，会抛出该异常。        |
| `std::underflow_error`  | 当发生数学下溢时，会抛出该异常。                |
可以使用多态接收标准异常，就不用考虑异常的类型
`catch(const exception &exception){}`
### 拦截所有异常
`catch(...){}`

## 自定义抛出异常
系统不一定会捕捉到所有的异常，此时可以在可能发生异常的位置自定义异常

```cpp
throw exceptionData;
```
抛出异常可以是任何类型，包括class



## 异常抛出声明
为了增强可读性和方便团队协作，如果函数内部可能抛出异常，可以在函数名后面声明抛出的异常类型
```cpp
void func(){} //可能抛出任何异常
void func() throw(int){} //可能会抛出int异常
void func() noexcept{} // 不会抛出任何异常
```